<?xml version="1.0" ?>
<!-- =================================================================================== -->
<!-- |    This document was autogenerated by xacro from src/hebi_description/urdf/kits/A-2085-06.urdf.xacro | -->
<!-- |    EDITING THIS FILE BY HAND IS NOT RECOMMENDED                                 | -->
<!-- =================================================================================== -->
<robot name="A-2085-06">
  <!-- This is a single xacro file you can include to get
  all of the HEBI components -->
  <link name="base_link"/>
  <joint name="base_joint" type="fixed">
    <origin rpy="0 0 0" xyz="0 0 0"/>
    <parent link="base_link"/>
    <child link="J1_base/body"/>
  </joint>
  <!-- Link definition -->
  <link name="J1_base/body">
    <visual>
      <origin rpy="0 0 0" xyz="0 0 0"/>
      <geometry>
        <mesh filename="meshes/X8.stl" scale="0.001 0.001 0.001"/>
      </geometry>
      <material name="red">
        <color rgba=".82 0.06 0.06 1"/>
      </material>
    </visual>
    <collision>
      <origin rpy="0 0 0" xyz="0 0 0"/>
      <geometry>
        <mesh filename="meshes/X8.stl" scale="0.001 0.001 0.001"/>
      </geometry>
    </collision>
    <inertial>
      <mass value="0.48"/>
      <origin rpy="0 0 0" xyz="-0.0145 -0.0031 0.0242"/>
      <inertia ixx="0.000246" ixy="0.0000444" ixz="0.0000266" iyy="0.000380" iyz="0.00000422" izz="0.000463"/>
    </inertial>
  </link>
  <gazebo reference="J1_base/body">
    <material>Gazebo/Red</material>
  </gazebo>
  <joint name="J1_base" type="continuous">
    <parent link="J1_base/body"/>
    <child link="bracket_1"/>
    <origin rpy="0 0 0" xyz="0 0 0.045"/>
    <axis xyz="0 0 1"/>
    <limit effort="20" velocity="3.142"/>
    <dynamics damping="0.5" friction="0.5"/>
  </joint>
  <link name="bracket_1">
    <visual>
      <origin rpy="1.5707963267948966 0 1.5707963267948966" xyz="0 0 0.005"/>
      <geometry>
        <mesh filename="meshes/PM-2149-01.stl" scale="0.001 0.001 0.001"/>
      </geometry>
      <material name="black">
        <color rgba="0.1 0.1 0.1 1"/>
      </material>
    </visual>
    <visual>
      <origin rpy="1.5707963267948966 0 0" xyz="0 -.03 .04"/>
      <geometry>
        <mesh filename="meshes/PM-2150-01R.stl" scale="0.001 0.001 0.001"/>
      </geometry>
      <material name="black">
        <color rgba="0.1 0.1 0.1 1"/>
      </material>
    </visual>
    <collision>
      <origin rpy="1.5707963267948966 0 1.5707963267948966" xyz="0 0 0.005"/>
      <geometry>
        <mesh filename="meshes/PM-2149-01.stl" scale="0.001 0.001 0.001"/>
      </geometry>
    </collision>
    <collision>
      <origin rpy="1.5707963267948966 0 0" xyz="0 -.03 .04"/>
      <geometry>
        <mesh filename="meshes/PM-2150-01R.stl" scale="0.001 0.001 0.001"/>
      </geometry>
    </collision>
    <!-- inertia is just modelled as small sphere, and could be improved. -->
    <inertial>
      <origin rpy="0 0 0" xyz="0 -0.01875 .0275"/>
      <mass value="0.215"/>
      <inertia ixx="0.00030960000000000004" ixy="0.0" ixz="0.0" iyy="0.00030960000000000004" iyz="0.0" izz="0.00030960000000000004"/>
    </inertial>
  </link>
  <gazebo reference="bracket_1">
    <material>Gazebo/Black</material>
  </gazebo>
  <joint name="bracket_1_J2_shoulder" type="fixed">
    <parent link="bracket_1"/>
    <child link="J2_shoulder/body"/>
    <origin rpy="1.5707963267948966 0 0" xyz="0 -.0375 .055"/>
  </joint>
  <!-- Link definition -->
  <link name="J2_shoulder/body">
    <visual>
      <origin rpy="0 0 0" xyz="0 0 0"/>
      <geometry>
        <mesh filename="meshes/X8.stl" scale="0.001 0.001 0.001"/>
      </geometry>
      <material name="red">
        <color rgba=".82 0.06 0.06 1"/>
      </material>
    </visual>
    <collision>
      <origin rpy="0 0 0" xyz="0 0 0"/>
      <geometry>
        <mesh filename="meshes/X8.stl" scale="0.001 0.001 0.001"/>
      </geometry>
    </collision>
    <inertial>
      <mass value="0.5"/>
      <origin rpy="0 0 0" xyz="-0.0145 -0.0031 0.0242"/>
      <inertia ixx="0.000246" ixy="0.0000444" ixz="0.0000266" iyy="0.000380" iyz="0.00000422" izz="0.000463"/>
    </inertial>
  </link>
  <gazebo reference="J2_shoulder/body">
    <material>Gazebo/Red</material>
  </gazebo>
  <joint name="J2_shoulder" type="continuous">
    <parent link="J2_shoulder/body"/>
    <child link="link_1"/>
    <origin rpy="0 0 0" xyz="0 0 0.045"/>
    <axis xyz="0 0 1"/>
    <limit effort="38" velocity="1.571"/>
    <dynamics damping="0.5" friction="0.5"/>
  </joint>
  <link name="link_1">
    <!-- Input Cap -->
    <visual>
      <origin rpy="0 0 0" xyz="0 0 0"/>
      <geometry>
        <mesh filename="meshes/A-2038-02.stl" scale="0.001 0.001 0.001"/>
      </geometry>
      <material name="black">
        <color rgba="0.1 0.1 0.1 1"/>
      </material>
    </visual>
    <collision>
      <origin rpy="0 0 0" xyz="0 0 0"/>
      <geometry>
        <mesh filename="meshes/A-2038-02.stl" scale="0.001 0.001 0.001"/>
      </geometry>
    </collision>
    <!-- Link Pipe -->
    <visual>
      <origin rpy="0 1.57075 0" xyz="0.1625 0 0.02"/>
      <geometry>
        <cylinder length="0.29960000000000003" radius=".016"/>
      </geometry>
      <material name="black">
        <color rgba="0.1 0.1 0.1 1"/>
      </material>
    </visual>
    <collision>
      <origin rpy="0 1.57075 0" xyz="0.1625 0 0.02"/>
      <geometry>
        <cylinder length="0.29960000000000003" radius=".016"/>
      </geometry>
    </collision>
    <visual>
      <origin rpy="3.141592653589793 0 0" xyz="0.325 -2.4492935982947064e-18 0.0"/>
      <geometry>
        <mesh filename="meshes/A-2039-02.stl" scale="0.001 0.001 0.001"/>
      </geometry>
      <material name="black">
        <color rgba="0.1 0.1 0.1 1"/>
      </material>
    </visual>
    <collision>
      <origin rpy="3.141592653589793 0 0" xyz="0.325 -2.4492935982947064e-18 0.0"/>
      <geometry>
        <mesh filename="meshes/A-2039-02.stl" scale="0.001 0.001 0.001"/>
      </geometry>
    </collision>
    <!-- Approximate inertia as thin rod about x axis -->
    <inertial>
      <origin rpy="0 0 0" xyz="0.1625 0 0.02"/>
      <mass value="0.402"/>
      <inertia ixx="8.04e-05" ixy="0.0" ixz="0.0" iyy="0.003618837500000001" iyz="0.0" izz="0.003618837500000001"/>
    </inertial>
  </link>
  <gazebo reference="link_1">
    <material>Gazebo/Black</material>
  </gazebo>
  <joint name="link_1/joint" type="fixed">
    <parent link="link_1"/>
    <child link="J3_elbow/body"/>
    <origin rpy="3.141592653589793 0 0" xyz="0.325 -2.4492935982947064e-18 0.0"/>
  </joint>
  <!-- Link definition -->
  <link name="J3_elbow/body">
    <visual>
      <origin rpy="0 0 0" xyz="0 0 0"/>
      <geometry>
        <mesh filename="meshes/X8.stl" scale="0.001 0.001 0.001"/>
      </geometry>
      <material name="red">
        <color rgba=".82 0.06 0.06 1"/>
      </material>
    </visual>
    <collision>
      <origin rpy="0 0 0" xyz="0 0 0"/>
      <geometry>
        <mesh filename="meshes/X8.stl" scale="0.001 0.001 0.001"/>
      </geometry>
    </collision>
    <inertial>
      <mass value="0.48"/>
      <origin rpy="0 0 0" xyz="-0.0145 -0.0031 0.0242"/>
      <inertia ixx="0.000246" ixy="0.0000444" ixz="0.0000266" iyy="0.000380" iyz="0.00000422" izz="0.000463"/>
    </inertial>
  </link>
  <gazebo reference="J3_elbow/body">
    <material>Gazebo/Red</material>
  </gazebo>
  <joint name="J3_elbow" type="continuous">
    <parent link="J3_elbow/body"/>
    <child link="link_2"/>
    <origin rpy="0 0 0" xyz="0 0 0.045"/>
    <axis xyz="0 0 1"/>
    <limit effort="20" velocity="3.142"/>
    <dynamics damping="0.5" friction="0.5"/>
  </joint>
  <link name="link_2">
    <!-- Input Cap -->
    <visual>
      <origin rpy="0 0 0" xyz="0 0 0"/>
      <geometry>
        <mesh filename="meshes/A-2038-02.stl" scale="0.001 0.001 0.001"/>
      </geometry>
      <material name="black">
        <color rgba="0.1 0.1 0.1 1"/>
      </material>
    </visual>
    <collision>
      <origin rpy="0 0 0" xyz="0 0 0"/>
      <geometry>
        <mesh filename="meshes/A-2038-02.stl" scale="0.001 0.001 0.001"/>
      </geometry>
    </collision>
    <!-- Link Pipe -->
    <visual>
      <origin rpy="0 1.57075 0" xyz="0.1625 0 0.02"/>
      <geometry>
        <cylinder length="0.29960000000000003" radius=".016"/>
      </geometry>
      <material name="black">
        <color rgba="0.1 0.1 0.1 1"/>
      </material>
    </visual>
    <collision>
      <origin rpy="0 1.57075 0" xyz="0.1625 0 0.02"/>
      <geometry>
        <cylinder length="0.29960000000000003" radius=".016"/>
      </geometry>
    </collision>
    <visual>
      <origin rpy="3.141592653589793 0 0" xyz="0.325 -2.4492935982947064e-18 0.0"/>
      <geometry>
        <mesh filename="meshes/A-2039-02.stl" scale="0.001 0.001 0.001"/>
      </geometry>
      <material name="black">
        <color rgba="0.1 0.1 0.1 1"/>
      </material>
    </visual>
    <collision>
      <origin rpy="3.141592653589793 0 0" xyz="0.325 -2.4492935982947064e-18 0.0"/>
      <geometry>
        <mesh filename="meshes/A-2039-02.stl" scale="0.001 0.001 0.001"/>
      </geometry>
    </collision>
    <!-- Approximate inertia as thin rod about x axis -->
    <inertial>
      <origin rpy="0 0 0" xyz="0.1625 0 0.02"/>
      <mass value="0.402"/>
      <inertia ixx="8.04e-05" ixy="0.0" ixz="0.0" iyy="0.003618837500000001" iyz="0.0" izz="0.003618837500000001"/>
    </inertial>
  </link>
  <gazebo reference="link_2">
    <material>Gazebo/Black</material>
  </gazebo>
  <joint name="link_2/joint" type="fixed">
    <parent link="link_2"/>
    <child link="J4_wrist1/body"/>
    <origin rpy="3.141592653589793 0 0" xyz="0.325 -2.4492935982947064e-18 0.0"/>
  </joint>
  <!-- Link definition -->
  <link name="J4_wrist1/body">
    <visual>
      <origin rpy="0 0 0" xyz="0 0 0"/>
      <geometry>
        <mesh filename="meshes/X5.stl" scale="0.001 0.001 0.001"/>
      </geometry>
      <material name="red">
        <color rgba=".82 0.06 0.06 1"/>
      </material>
    </visual>
    <collision>
      <origin rpy="0 0 0" xyz="0 0 0"/>
      <geometry>
        <mesh filename="meshes/X5.stl" scale="0.001 0.001 0.001"/>
      </geometry>
    </collision>
    <inertial>
      <mass value="0.315"/>
      <origin rpy="0 0 0" xyz="-0.0142 -0.0031 0.0165"/>
      <inertia ixx="0.00015" ixy="0.0000341" ixz="0.0000118" iyy="0.000255" iyz="0.00000229" izz="0.000350"/>
    </inertial>
  </link>
  <gazebo reference="J4_wrist1/body">
    <material>Gazebo/Red</material>
  </gazebo>
  <joint name="J4_wrist1" type="continuous">
    <parent link="J4_wrist1/body"/>
    <child link="bracket_2"/>
    <origin rpy="0 0 0" xyz="0 0 0.031"/>
    <axis xyz="0 0 1"/>
    <limit effort="2.5" velocity="9.425"/>
    <dynamics damping="0.1" friction="0.1"/>
  </joint>
  <link name="bracket_2">
    <visual>
      <origin rpy="1.5707963267948966 0 -1.5707963267948966" xyz="0 0 0"/>
      <geometry>
        <mesh filename="meshes/PM-2132-01R.stl" scale="0.001 0.001 0.001"/>
      </geometry>
      <material name="beige">
        <color rgba="0.96 0.945 0.871 1"/>
      </material>
    </visual>
    <collision>
      <origin rpy="1.5707963267948966 0 -1.5707963267948966" xyz="0 0 0"/>
      <geometry>
        <mesh filename="meshes/PM-2132-01R.stl" scale="0.001 0.001 0.001"/>
      </geometry>
    </collision>
    <!-- inertia is just modelled as small sphere, and could be improved. -->
    <inertial>
      <origin rpy="0 0 0" xyz="0 -.0215 .02"/>
      <mass value="0.1"/>
      <inertia ixx="0.000144" ixy="0.0" ixz="0.0" iyy="0.000144" iyz="0.0" izz="0.000144"/>
    </inertial>
  </link>
  <gazebo reference="bracket_2">
    <visual>
      <material>
        <ambient>0.96 0.945 0.871 1</ambient>
        <diffuse>0.96 0.945 0.871 1</diffuse>
      </material>
    </visual>
  </gazebo>
  <joint name="bracket_2_J5_wrist2" type="fixed">
    <parent link="bracket_2"/>
    <child link="J5_wrist2/body"/>
    <origin rpy="1.5707963267948966 0 0" xyz="0 -.043 .04"/>
  </joint>
  <!-- Link definition -->
  <link name="J5_wrist2/body">
    <visual>
      <origin rpy="0 0 0" xyz="0 0 0"/>
      <geometry>
        <mesh filename="meshes/X5.stl" scale="0.001 0.001 0.001"/>
      </geometry>
      <material name="red">
        <color rgba=".82 0.06 0.06 1"/>
      </material>
    </visual>
    <collision>
      <origin rpy="0 0 0" xyz="0 0 0"/>
      <geometry>
        <mesh filename="meshes/X5.stl" scale="0.001 0.001 0.001"/>
      </geometry>
    </collision>
    <inertial>
      <mass value="0.315"/>
      <origin rpy="0 0 0" xyz="-0.0142 -0.0031 0.0165"/>
      <inertia ixx="0.00015" ixy="0.0000341" ixz="0.0000118" iyy="0.000255" iyz="0.00000229" izz="0.000350"/>
    </inertial>
  </link>
  <gazebo reference="J5_wrist2/body">
    <material>Gazebo/Red</material>
  </gazebo>
  <joint name="J5_wrist2" type="continuous">
    <parent link="J5_wrist2/body"/>
    <child link="bracket_3"/>
    <origin rpy="0 0 0" xyz="0 0 0.031"/>
    <axis xyz="0 0 1"/>
    <limit effort="2.5" velocity="9.425"/>
    <dynamics damping="0.1" friction="0.1"/>
  </joint>
  <link name="bracket_3">
    <visual>
      <origin rpy="1.5707963267948966 0 -1.5707963267948966" xyz="0 0 0"/>
      <geometry>
        <mesh filename="meshes/PM-2132-01R.stl" scale="0.001 0.001 0.001"/>
      </geometry>
      <material name="beige">
        <color rgba="0.96 0.945 0.871 1"/>
      </material>
    </visual>
    <collision>
      <origin rpy="1.5707963267948966 0 -1.5707963267948966" xyz="0 0 0"/>
      <geometry>
        <mesh filename="meshes/PM-2132-01R.stl" scale="0.001 0.001 0.001"/>
      </geometry>
    </collision>
    <!-- inertia is just modelled as small sphere, and could be improved. -->
    <inertial>
      <origin rpy="0 0 0" xyz="0 -.0215 .02"/>
      <mass value="0.1"/>
      <inertia ixx="0.000144" ixy="0.0" ixz="0.0" iyy="0.000144" iyz="0.0" izz="0.000144"/>
    </inertial>
  </link>
  <gazebo reference="bracket_3">
    <visual>
      <material>
        <ambient>0.96 0.945 0.871 1</ambient>
        <diffuse>0.96 0.945 0.871 1</diffuse>
      </material>
    </visual>
  </gazebo>
  <joint name="bracket_3_J6_wrist3" type="fixed">
    <parent link="bracket_3"/>
    <child link="J6_wrist3/body"/>
    <origin rpy="1.5707963267948966 0 0" xyz="0 -.043 .04"/>
  </joint>
  <!-- Link definition -->
  <link name="J6_wrist3/body">
    <visual>
      <origin rpy="0 0 0" xyz="0 0 0"/>
      <geometry>
        <mesh filename="meshes/X5.stl" scale="0.001 0.001 0.001"/>
      </geometry>
      <material name="red">
        <color rgba=".82 0.06 0.06 1"/>
      </material>
    </visual>
    <collision>
      <origin rpy="0 0 0" xyz="0 0 0"/>
      <geometry>
        <mesh filename="meshes/X5.stl" scale="0.001 0.001 0.001"/>
      </geometry>
    </collision>
    <inertial>
      <mass value="0.315"/>
      <origin rpy="0 0 0" xyz="-0.0142 -0.0031 0.0165"/>
      <inertia ixx="0.00015" ixy="0.0000341" ixz="0.0000118" iyy="0.000255" iyz="0.00000229" izz="0.000350"/>
    </inertial>
  </link>
  <gazebo reference="J6_wrist3/body">
    <material>Gazebo/Red</material>
  </gazebo>
  <joint name="J6_wrist3" type="continuous">
    <parent link="J6_wrist3/body"/>
    <child link="end_effector_1"/>
    <origin rpy="0 0 0" xyz="0 0 0.031"/>
    <axis xyz="0 0 1"/>
    <limit effort="2.5" velocity="9.425"/>
    <dynamics damping="0.1" friction="0.1"/>
  </joint>
  <link name="end_effector_1">
    <visual>
      <origin rpy="0 0 0" xyz="0 0 0.0005"/>
      <geometry>
        <box size="0.001 0.001 0.001"/>
      </geometry>
    </visual>
    <collision>
      <origin rpy="0 0 0" xyz="0 0 0.0005"/>
      <geometry>
        <box size="0.001 0.001 0.001"/>
      </geometry>
    </collision>
    <inertial>
      <origin rpy="0 0 0" xyz="0 0 0"/>
      <mass value="0.001"/>
      <inertia ixx="4.000000000000001e-06" ixy="0" ixz="0" iyy="4.000000000000001e-06" iyz="0" izz="4.000000000000001e-06"/>
    </inertial>
  </link>
  <link name="end_effector_1/output"/>
  <joint name="end_effector_1/output_joint" type="fixed">
    <origin rpy="0 0 0" xyz="0 0 0"/>
    <parent link="end_effector_1"/>
    <child link="end_effector_1/output"/>
  </joint>
</robot>
